[2023-05-17T13:37:25.880+0200] {taskinstance.py:1125} INFO - Dependencies all met for dep_context=non-requeueable deps ti=<TaskInstance: etl_news_pipeline.extract_data scheduled__2023-05-16T00:00:00+00:00 [queued]>
[2023-05-17T13:37:26.034+0200] {taskinstance.py:1125} INFO - Dependencies all met for dep_context=requeueable deps ti=<TaskInstance: etl_news_pipeline.extract_data scheduled__2023-05-16T00:00:00+00:00 [queued]>
[2023-05-17T13:37:26.034+0200] {taskinstance.py:1331} INFO - Starting attempt 3 of 2
[2023-05-17T13:37:26.094+0200] {taskinstance.py:1350} INFO - Executing <Task(BashOperator): extract_data> on 2023-05-16 00:00:00+00:00
[2023-05-17T13:37:26.155+0200] {standard_task_runner.py:57} INFO - Started process 1838 to run task
[2023-05-17T13:37:26.174+0200] {standard_task_runner.py:84} INFO - Running: ['airflow', 'tasks', 'run', 'etl_news_pipeline', 'extract_data', 'scheduled__2023-05-16T00:00:00+00:00', '--job-id', '1877', '--raw', '--subdir', 'DAGS_FOLDER/etl_pipeline.py', '--cfg-path', '/var/folders/qv/qkzfd8cs7hdftb0synd9cw3h0000gn/T/tmpyhjljg2s']
[2023-05-17T13:37:26.178+0200] {standard_task_runner.py:85} INFO - Job 1877: Subtask extract_data
[2023-05-17T13:37:26.412+0200] {task_command.py:410} INFO - Running <TaskInstance: etl_news_pipeline.extract_data scheduled__2023-05-16T00:00:00+00:00 [running]> on host niyants-mbp.fritz.box
[2023-05-17T13:37:26.798+0200] {taskinstance.py:1568} INFO - Exporting env vars: AIRFLOW_CTX_DAG_OWNER='airflow' AIRFLOW_CTX_DAG_ID='etl_news_pipeline' AIRFLOW_CTX_TASK_ID='extract_data' AIRFLOW_CTX_EXECUTION_DATE='2023-05-16T00:00:00+00:00' AIRFLOW_CTX_TRY_NUMBER='3' AIRFLOW_CTX_DAG_RUN_ID='scheduled__2023-05-16T00:00:00+00:00'
[2023-05-17T13:37:26.800+0200] {subprocess.py:63} INFO - Tmp dir root location: 
 /var/folders/qv/qkzfd8cs7hdftb0synd9cw3h0000gn/T
[2023-05-17T13:37:26.801+0200] {subprocess.py:75} INFO - Running command: ['/bin/bash', '-c', 'python /Users/niyantmehta/Spiced/ETL_Pipeline/airflow/ETL_dags/extract.py extract_data']
[2023-05-17T13:37:26.834+0200] {subprocess.py:86} INFO - Output:
[2023-05-17T13:38:36.630+0200] {local_task_job_runner.py:298} WARNING - State of this instance has been externally set to None. Terminating instance.
[2023-05-17T13:38:37.036+0200] {process_utils.py:131} INFO - Sending 15 to group 1838. PIDs of all processes in the group: [1917, 1838]
[2023-05-17T13:38:37.048+0200] {process_utils.py:86} INFO - Sending the signal 15 to group 1838
[2023-05-17T13:38:37.260+0200] {taskinstance.py:1540} ERROR - Received SIGTERM. Terminating subprocesses.
[2023-05-17T13:38:37.415+0200] {subprocess.py:104} INFO - Sending SIGTERM signal to process group
[2023-05-17T13:38:37.837+0200] {taskinstance.py:1847} ERROR - Task failed with exception
Traceback (most recent call last):
  File "/Users/niyantmehta/opt/anaconda3/envs/finalvenv/lib/python3.11/site-packages/airflow/operators/bash.py", line 201, in execute
    result = self.subprocess_hook.run_command(
             ^^^^^^^^^^^^^^^^^^^^^^^^^^^^^^^^^
  File "/Users/niyantmehta/opt/anaconda3/envs/finalvenv/lib/python3.11/site-packages/airflow/hooks/subprocess.py", line 91, in run_command
    for raw_line in iter(self.sub_process.stdout.readline, b""):
  File "/Users/niyantmehta/opt/anaconda3/envs/finalvenv/lib/python3.11/site-packages/airflow/models/taskinstance.py", line 1542, in signal_handler
    raise AirflowException("Task received SIGTERM signal")
airflow.exceptions.AirflowException: Task received SIGTERM signal
[2023-05-17T13:38:37.878+0200] {taskinstance.py:1368} INFO - Marking task as FAILED. dag_id=etl_news_pipeline, task_id=extract_data, execution_date=20230516T000000, start_date=20230517T113725, end_date=20230517T113837
[2023-05-17T13:38:37.947+0200] {standard_task_runner.py:104} ERROR - Failed to execute job 1877 for task extract_data ((psycopg2.errors.ForeignKeyViolation) insert or update on table "task_fail" violates foreign key constraint "task_fail_ti_fkey"
DETAIL:  Key (dag_id, task_id, run_id, map_index)=(etl_news_pipeline, extract_data, scheduled__2023-05-16T00:00:00+00:00, -1) is not present in table "task_instance".

[SQL: INSERT INTO task_fail (task_id, dag_id, run_id, map_index, start_date, end_date, duration) VALUES (%(task_id)s, %(dag_id)s, %(run_id)s, %(map_index)s, %(start_date)s, %(end_date)s, %(duration)s) RETURNING task_fail.id]
[parameters: {'task_id': 'extract_data', 'dag_id': 'etl_news_pipeline', 'run_id': 'scheduled__2023-05-16T00:00:00+00:00', 'map_index': -1, 'start_date': datetime.datetime(2023, 5, 17, 11, 37, 25, 882693, tzinfo=Timezone('UTC')), 'end_date': datetime.datetime(2023, 5, 17, 11, 38, 37, 866836, tzinfo=Timezone('UTC')), 'duration': 71}]
(Background on this error at: https://sqlalche.me/e/14/gkpj); 1838)
[2023-05-17T13:38:37.973+0200] {process_utils.py:79} INFO - Process psutil.Process(pid=1917, status='terminated', started='13:37:26') (1917) terminated with exit code None
[2023-05-17T13:38:37.975+0200] {process_utils.py:79} INFO - Process psutil.Process(pid=1838, status='terminated', exitcode=1, started='13:37:26') (1838) terminated with exit code 1
